{
 "cells": [
  {
   "cell_type": "markdown",
   "metadata": {},
   "source": [
    "# Practice Notebook - Unit Tests and Edge Cases"
   ]
  },
  {
   "cell_type": "markdown",
   "metadata": {},
   "source": [
    "Below we have some code that makes a list of specific letters found in any string. If you run it, you can see what it does."
   ]
  },
  {
   "cell_type": "code",
   "execution_count": 1,
   "metadata": {},
   "outputs": [
    {
     "name": "stdout",
     "output_type": "stream",
     "text": [
      "['a', 'b']\n"
     ]
    }
   ],
   "source": [
    "import re \n",
    "  \n",
    "my_txt = \"An investment in knowledge pays the best interest.\"\n",
    "\n",
    "def LetterCompiler(txt):\n",
    "    result = re.findall(r'([a-c]).', txt)\n",
    "    return result\n",
    "\n",
    "print(LetterCompiler(my_txt))"
   ]
  },
  {
   "cell_type": "markdown",
   "metadata": {},
   "source": [
    "From the output, you can see that the `LetterCompiler( )` function finds all matches for the letters a through c in an input string if followed by another character and returns them as a list of strings, with each string representing one match. Nice.\n",
    "<br><br>\n",
    "But can we be sure that this function will always do what we expect it to do? We need to write code to help us catch mistakes, errors and bugs.  This code should automate the process of checking if the returned value of our code matches the expectations by dynamically feeding into it test cases.  Since we're dynamically feeding in different strings, it would be prudent to create unit tests for our code. We can use the module **unittest** for this. \n",
    "<br><br>\n",
    "Fill in the blanks below to create an automatic unint test that verifies whether input strings have the correct list of string matches."
   ]
  },
  {
   "cell_type": "code",
   "execution_count": 2,
   "metadata": {},
   "outputs": [],
   "source": [
    "import unittest\n",
    "\n",
    "class TestCompiler(unittest.TestCase):\n",
    "    def test_basic(self):\n",
    "        testcase = \"The best preparation for tomorrow is doing your best today.\"\n",
    "        expected = ['b', 'a', 'a', 'b', 'a']\n",
    "        self.assertEqual(LetterCompiler(testcase), expected)"
   ]
  },
  {
   "cell_type": "markdown",
   "metadata": {},
   "source": [
    "Now that your automatic test is coded, you need to call the `unittest.main( )` function to run the test.  It is important to note that the configuration for running unit tests in Jupyter is different than running unit tests from the command line. Running `unittest.main( )` in Jupyter **will result in an error**.  You can see this by runnig the following cell to execute your automatic test."
   ]
  },
  {
   "cell_type": "code",
   "execution_count": 3,
   "metadata": {},
   "outputs": [
    {
     "name": "stderr",
     "output_type": "stream",
     "text": [
      "usage: ipykernel_launcher.py [-h] [-v] [-q] [--locals] [-f] [-c] [-b]\n",
      "                             [-k TESTNAMEPATTERNS]\n",
      "                             [tests ...]\n",
      "ipykernel_launcher.py: error: argument -f/--failfast: ignored explicit argument '/home/luis-mendoza/.local/share/jupyter/runtime/kernel-v2-438850ADymw27ocLM.json'\n"
     ]
    },
    {
     "ename": "AttributeError",
     "evalue": "'tuple' object has no attribute 'tb_frame'",
     "output_type": "error",
     "traceback": [
      "\u001b[0;31m---------------------------------------------------------------------------\u001b[0m",
      "\u001b[0;31mArgumentError\u001b[0m                             Traceback (most recent call last)",
      "File \u001b[0;32m~/anaconda3/lib/python3.10/argparse.py:1859\u001b[0m, in \u001b[0;36mArgumentParser.parse_known_args\u001b[0;34m(self, args, namespace)\u001b[0m\n\u001b[1;32m   1858\u001b[0m \u001b[39mtry\u001b[39;00m:\n\u001b[0;32m-> 1859\u001b[0m     namespace, args \u001b[39m=\u001b[39m \u001b[39mself\u001b[39;49m\u001b[39m.\u001b[39;49m_parse_known_args(args, namespace)\n\u001b[1;32m   1860\u001b[0m \u001b[39mexcept\u001b[39;00m ArgumentError:\n",
      "File \u001b[0;32m~/anaconda3/lib/python3.10/argparse.py:2072\u001b[0m, in \u001b[0;36mArgumentParser._parse_known_args\u001b[0;34m(self, arg_strings, namespace)\u001b[0m\n\u001b[1;32m   2071\u001b[0m     \u001b[39m# consume the next optional and any arguments for it\u001b[39;00m\n\u001b[0;32m-> 2072\u001b[0m     start_index \u001b[39m=\u001b[39m consume_optional(start_index)\n\u001b[1;32m   2074\u001b[0m \u001b[39m# consume any positionals following the last Optional\u001b[39;00m\n",
      "File \u001b[0;32m~/anaconda3/lib/python3.10/argparse.py:1994\u001b[0m, in \u001b[0;36mArgumentParser._parse_known_args.<locals>.consume_optional\u001b[0;34m(start_index)\u001b[0m\n\u001b[1;32m   1993\u001b[0m         msg \u001b[39m=\u001b[39m _(\u001b[39m'\u001b[39m\u001b[39mignored explicit argument \u001b[39m\u001b[39m%r\u001b[39;00m\u001b[39m'\u001b[39m)\n\u001b[0;32m-> 1994\u001b[0m         \u001b[39mraise\u001b[39;00m ArgumentError(action, msg \u001b[39m%\u001b[39m explicit_arg)\n\u001b[1;32m   1996\u001b[0m \u001b[39m# if there is no explicit argument, try to match the\u001b[39;00m\n\u001b[1;32m   1997\u001b[0m \u001b[39m# optional's string arguments with the following strings\u001b[39;00m\n\u001b[1;32m   1998\u001b[0m \u001b[39m# if successful, exit the loop\u001b[39;00m\n\u001b[1;32m   1999\u001b[0m \u001b[39melse\u001b[39;00m:\n",
      "\u001b[0;31mArgumentError\u001b[0m: argument -f/--failfast: ignored explicit argument '/home/luis-mendoza/.local/share/jupyter/runtime/kernel-v2-438850ADymw27ocLM.json'",
      "\nDuring handling of the above exception, another exception occurred:\n",
      "\u001b[0;31mSystemExit\u001b[0m                                Traceback (most recent call last)",
      "    \u001b[0;31m[... skipping hidden 1 frame]\u001b[0m\n",
      "Cell \u001b[0;32mIn[3], line 1\u001b[0m\n\u001b[0;32m----> 1\u001b[0m unittest\u001b[39m.\u001b[39;49mmain()\n",
      "File \u001b[0;32m~/anaconda3/lib/python3.10/unittest/main.py:100\u001b[0m, in \u001b[0;36mTestProgram.__init__\u001b[0;34m(self, module, defaultTest, argv, testRunner, testLoader, exit, verbosity, failfast, catchbreak, buffer, warnings, tb_locals)\u001b[0m\n\u001b[1;32m     99\u001b[0m \u001b[39mself\u001b[39m\u001b[39m.\u001b[39mprogName \u001b[39m=\u001b[39m os\u001b[39m.\u001b[39mpath\u001b[39m.\u001b[39mbasename(argv[\u001b[39m0\u001b[39m])\n\u001b[0;32m--> 100\u001b[0m \u001b[39mself\u001b[39;49m\u001b[39m.\u001b[39;49mparseArgs(argv)\n\u001b[1;32m    101\u001b[0m \u001b[39mself\u001b[39m\u001b[39m.\u001b[39mrunTests()\n",
      "File \u001b[0;32m~/anaconda3/lib/python3.10/unittest/main.py:133\u001b[0m, in \u001b[0;36mTestProgram.parseArgs\u001b[0;34m(self, argv)\u001b[0m\n\u001b[1;32m    132\u001b[0m \u001b[39melse\u001b[39;00m:\n\u001b[0;32m--> 133\u001b[0m     \u001b[39mself\u001b[39;49m\u001b[39m.\u001b[39;49m_main_parser\u001b[39m.\u001b[39;49mparse_args(argv[\u001b[39m1\u001b[39;49m:], \u001b[39mself\u001b[39;49m)\n\u001b[1;32m    135\u001b[0m \u001b[39mif\u001b[39;00m \u001b[39mself\u001b[39m\u001b[39m.\u001b[39mtests:\n",
      "File \u001b[0;32m~/anaconda3/lib/python3.10/argparse.py:1826\u001b[0m, in \u001b[0;36mArgumentParser.parse_args\u001b[0;34m(self, args, namespace)\u001b[0m\n\u001b[1;32m   1825\u001b[0m \u001b[39mdef\u001b[39;00m \u001b[39mparse_args\u001b[39m(\u001b[39mself\u001b[39m, args\u001b[39m=\u001b[39m\u001b[39mNone\u001b[39;00m, namespace\u001b[39m=\u001b[39m\u001b[39mNone\u001b[39;00m):\n\u001b[0;32m-> 1826\u001b[0m     args, argv \u001b[39m=\u001b[39m \u001b[39mself\u001b[39;49m\u001b[39m.\u001b[39;49mparse_known_args(args, namespace)\n\u001b[1;32m   1827\u001b[0m     \u001b[39mif\u001b[39;00m argv:\n",
      "File \u001b[0;32m~/anaconda3/lib/python3.10/argparse.py:1862\u001b[0m, in \u001b[0;36mArgumentParser.parse_known_args\u001b[0;34m(self, args, namespace)\u001b[0m\n\u001b[1;32m   1861\u001b[0m         err \u001b[39m=\u001b[39m _sys\u001b[39m.\u001b[39mexc_info()[\u001b[39m1\u001b[39m]\n\u001b[0;32m-> 1862\u001b[0m         \u001b[39mself\u001b[39;49m\u001b[39m.\u001b[39;49merror(\u001b[39mstr\u001b[39;49m(err))\n\u001b[1;32m   1863\u001b[0m \u001b[39melse\u001b[39;00m:\n",
      "File \u001b[0;32m~/anaconda3/lib/python3.10/argparse.py:2587\u001b[0m, in \u001b[0;36mArgumentParser.error\u001b[0;34m(self, message)\u001b[0m\n\u001b[1;32m   2586\u001b[0m args \u001b[39m=\u001b[39m {\u001b[39m'\u001b[39m\u001b[39mprog\u001b[39m\u001b[39m'\u001b[39m: \u001b[39mself\u001b[39m\u001b[39m.\u001b[39mprog, \u001b[39m'\u001b[39m\u001b[39mmessage\u001b[39m\u001b[39m'\u001b[39m: message}\n\u001b[0;32m-> 2587\u001b[0m \u001b[39mself\u001b[39;49m\u001b[39m.\u001b[39;49mexit(\u001b[39m2\u001b[39;49m, _(\u001b[39m'\u001b[39;49m\u001b[39m%(prog)s\u001b[39;49;00m\u001b[39m: error: \u001b[39;49m\u001b[39m%(message)s\u001b[39;49;00m\u001b[39m\\n\u001b[39;49;00m\u001b[39m'\u001b[39;49m) \u001b[39m%\u001b[39;49m args)\n",
      "File \u001b[0;32m~/anaconda3/lib/python3.10/argparse.py:2574\u001b[0m, in \u001b[0;36mArgumentParser.exit\u001b[0;34m(self, status, message)\u001b[0m\n\u001b[1;32m   2573\u001b[0m     \u001b[39mself\u001b[39m\u001b[39m.\u001b[39m_print_message(message, _sys\u001b[39m.\u001b[39mstderr)\n\u001b[0;32m-> 2574\u001b[0m _sys\u001b[39m.\u001b[39;49mexit(status)\n",
      "\u001b[0;31mSystemExit\u001b[0m: 2",
      "\nDuring handling of the above exception, another exception occurred:\n",
      "\u001b[0;31mAttributeError\u001b[0m                            Traceback (most recent call last)",
      "    \u001b[0;31m[... skipping hidden 1 frame]\u001b[0m\n",
      "File \u001b[0;32m~/anaconda3/lib/python3.10/site-packages/IPython/core/interactiveshell.py:2092\u001b[0m, in \u001b[0;36mInteractiveShell.showtraceback\u001b[0;34m(self, exc_tuple, filename, tb_offset, exception_only, running_compiled_code)\u001b[0m\n\u001b[1;32m   2089\u001b[0m \u001b[39mif\u001b[39;00m exception_only:\n\u001b[1;32m   2090\u001b[0m     stb \u001b[39m=\u001b[39m [\u001b[39m'\u001b[39m\u001b[39mAn exception has occurred, use \u001b[39m\u001b[39m%\u001b[39m\u001b[39mtb to see \u001b[39m\u001b[39m'\u001b[39m\n\u001b[1;32m   2091\u001b[0m            \u001b[39m'\u001b[39m\u001b[39mthe full traceback.\u001b[39m\u001b[39m\\n\u001b[39;00m\u001b[39m'\u001b[39m]\n\u001b[0;32m-> 2092\u001b[0m     stb\u001b[39m.\u001b[39mextend(\u001b[39mself\u001b[39;49m\u001b[39m.\u001b[39;49mInteractiveTB\u001b[39m.\u001b[39;49mget_exception_only(etype,\n\u001b[1;32m   2093\u001b[0m                                                      value))\n\u001b[1;32m   2094\u001b[0m \u001b[39melse\u001b[39;00m:\n\u001b[1;32m   2095\u001b[0m     \u001b[39mtry\u001b[39;00m:\n\u001b[1;32m   2096\u001b[0m         \u001b[39m# Exception classes can customise their traceback - we\u001b[39;00m\n\u001b[1;32m   2097\u001b[0m         \u001b[39m# use this in IPython.parallel for exceptions occurring\u001b[39;00m\n\u001b[1;32m   2098\u001b[0m         \u001b[39m# in the engines. This should return a list of strings.\u001b[39;00m\n",
      "File \u001b[0;32m~/anaconda3/lib/python3.10/site-packages/IPython/core/ultratb.py:644\u001b[0m, in \u001b[0;36mListTB.get_exception_only\u001b[0;34m(self, etype, value)\u001b[0m\n\u001b[1;32m    636\u001b[0m \u001b[39mdef\u001b[39;00m \u001b[39mget_exception_only\u001b[39m(\u001b[39mself\u001b[39m, etype, value):\n\u001b[1;32m    637\u001b[0m     \u001b[39m\"\"\"Only print the exception type and message, without a traceback.\u001b[39;00m\n\u001b[1;32m    638\u001b[0m \n\u001b[1;32m    639\u001b[0m \u001b[39m    Parameters\u001b[39;00m\n\u001b[0;32m   (...)\u001b[0m\n\u001b[1;32m    642\u001b[0m \u001b[39m    value : exception value\u001b[39;00m\n\u001b[1;32m    643\u001b[0m \u001b[39m    \"\"\"\u001b[39;00m\n\u001b[0;32m--> 644\u001b[0m     \u001b[39mreturn\u001b[39;00m ListTB\u001b[39m.\u001b[39;49mstructured_traceback(\u001b[39mself\u001b[39;49m, etype, value)\n",
      "File \u001b[0;32m~/anaconda3/lib/python3.10/site-packages/IPython/core/ultratb.py:511\u001b[0m, in \u001b[0;36mListTB.structured_traceback\u001b[0;34m(self, etype, evalue, etb, tb_offset, context)\u001b[0m\n\u001b[1;32m    508\u001b[0m     chained_exc_ids\u001b[39m.\u001b[39madd(\u001b[39mid\u001b[39m(exception[\u001b[39m1\u001b[39m]))\n\u001b[1;32m    509\u001b[0m     chained_exceptions_tb_offset \u001b[39m=\u001b[39m \u001b[39m0\u001b[39m\n\u001b[1;32m    510\u001b[0m     out_list \u001b[39m=\u001b[39m (\n\u001b[0;32m--> 511\u001b[0m         \u001b[39mself\u001b[39;49m\u001b[39m.\u001b[39;49mstructured_traceback(\n\u001b[1;32m    512\u001b[0m             etype, evalue, (etb, chained_exc_ids),\n\u001b[1;32m    513\u001b[0m             chained_exceptions_tb_offset, context)\n\u001b[1;32m    514\u001b[0m         \u001b[39m+\u001b[39m chained_exception_message\n\u001b[1;32m    515\u001b[0m         \u001b[39m+\u001b[39m out_list)\n\u001b[1;32m    517\u001b[0m \u001b[39mreturn\u001b[39;00m out_list\n",
      "File \u001b[0;32m~/anaconda3/lib/python3.10/site-packages/IPython/core/ultratb.py:1310\u001b[0m, in \u001b[0;36mAutoFormattedTB.structured_traceback\u001b[0;34m(self, etype, value, tb, tb_offset, number_of_lines_of_context)\u001b[0m\n\u001b[1;32m   1308\u001b[0m \u001b[39melse\u001b[39;00m:\n\u001b[1;32m   1309\u001b[0m     \u001b[39mself\u001b[39m\u001b[39m.\u001b[39mtb \u001b[39m=\u001b[39m tb\n\u001b[0;32m-> 1310\u001b[0m \u001b[39mreturn\u001b[39;00m FormattedTB\u001b[39m.\u001b[39;49mstructured_traceback(\n\u001b[1;32m   1311\u001b[0m     \u001b[39mself\u001b[39;49m, etype, value, tb, tb_offset, number_of_lines_of_context)\n",
      "File \u001b[0;32m~/anaconda3/lib/python3.10/site-packages/IPython/core/ultratb.py:1199\u001b[0m, in \u001b[0;36mFormattedTB.structured_traceback\u001b[0;34m(self, etype, value, tb, tb_offset, number_of_lines_of_context)\u001b[0m\n\u001b[1;32m   1196\u001b[0m mode \u001b[39m=\u001b[39m \u001b[39mself\u001b[39m\u001b[39m.\u001b[39mmode\n\u001b[1;32m   1197\u001b[0m \u001b[39mif\u001b[39;00m mode \u001b[39min\u001b[39;00m \u001b[39mself\u001b[39m\u001b[39m.\u001b[39mverbose_modes:\n\u001b[1;32m   1198\u001b[0m     \u001b[39m# Verbose modes need a full traceback\u001b[39;00m\n\u001b[0;32m-> 1199\u001b[0m     \u001b[39mreturn\u001b[39;00m VerboseTB\u001b[39m.\u001b[39;49mstructured_traceback(\n\u001b[1;32m   1200\u001b[0m         \u001b[39mself\u001b[39;49m, etype, value, tb, tb_offset, number_of_lines_of_context\n\u001b[1;32m   1201\u001b[0m     )\n\u001b[1;32m   1202\u001b[0m \u001b[39melif\u001b[39;00m mode \u001b[39m==\u001b[39m \u001b[39m'\u001b[39m\u001b[39mMinimal\u001b[39m\u001b[39m'\u001b[39m:\n\u001b[1;32m   1203\u001b[0m     \u001b[39mreturn\u001b[39;00m ListTB\u001b[39m.\u001b[39mget_exception_only(\u001b[39mself\u001b[39m, etype, value)\n",
      "File \u001b[0;32m~/anaconda3/lib/python3.10/site-packages/IPython/core/ultratb.py:1052\u001b[0m, in \u001b[0;36mVerboseTB.structured_traceback\u001b[0;34m(self, etype, evalue, etb, tb_offset, number_of_lines_of_context)\u001b[0m\n\u001b[1;32m   1043\u001b[0m \u001b[39mdef\u001b[39;00m \u001b[39mstructured_traceback\u001b[39m(\n\u001b[1;32m   1044\u001b[0m     \u001b[39mself\u001b[39m,\n\u001b[1;32m   1045\u001b[0m     etype: \u001b[39mtype\u001b[39m,\n\u001b[0;32m   (...)\u001b[0m\n\u001b[1;32m   1049\u001b[0m     number_of_lines_of_context: \u001b[39mint\u001b[39m \u001b[39m=\u001b[39m \u001b[39m5\u001b[39m,\n\u001b[1;32m   1050\u001b[0m ):\n\u001b[1;32m   1051\u001b[0m     \u001b[39m\"\"\"Return a nice text document describing the traceback.\"\"\"\u001b[39;00m\n\u001b[0;32m-> 1052\u001b[0m     formatted_exception \u001b[39m=\u001b[39m \u001b[39mself\u001b[39;49m\u001b[39m.\u001b[39;49mformat_exception_as_a_whole(etype, evalue, etb, number_of_lines_of_context,\n\u001b[1;32m   1053\u001b[0m                                                            tb_offset)\n\u001b[1;32m   1055\u001b[0m     colors \u001b[39m=\u001b[39m \u001b[39mself\u001b[39m\u001b[39m.\u001b[39mColors  \u001b[39m# just a shorthand + quicker name lookup\u001b[39;00m\n\u001b[1;32m   1056\u001b[0m     colorsnormal \u001b[39m=\u001b[39m colors\u001b[39m.\u001b[39mNormal  \u001b[39m# used a lot\u001b[39;00m\n",
      "File \u001b[0;32m~/anaconda3/lib/python3.10/site-packages/IPython/core/ultratb.py:953\u001b[0m, in \u001b[0;36mVerboseTB.format_exception_as_a_whole\u001b[0;34m(self, etype, evalue, etb, number_of_lines_of_context, tb_offset)\u001b[0m\n\u001b[1;32m    950\u001b[0m \u001b[39massert\u001b[39;00m \u001b[39misinstance\u001b[39m(tb_offset, \u001b[39mint\u001b[39m)\n\u001b[1;32m    951\u001b[0m head \u001b[39m=\u001b[39m \u001b[39mself\u001b[39m\u001b[39m.\u001b[39mprepare_header(etype, \u001b[39mself\u001b[39m\u001b[39m.\u001b[39mlong_header)\n\u001b[1;32m    952\u001b[0m records \u001b[39m=\u001b[39m (\n\u001b[0;32m--> 953\u001b[0m     \u001b[39mself\u001b[39;49m\u001b[39m.\u001b[39;49mget_records(etb, number_of_lines_of_context, tb_offset) \u001b[39mif\u001b[39;00m etb \u001b[39melse\u001b[39;00m []\n\u001b[1;32m    954\u001b[0m )\n\u001b[1;32m    956\u001b[0m frames \u001b[39m=\u001b[39m []\n\u001b[1;32m    957\u001b[0m skipped \u001b[39m=\u001b[39m \u001b[39m0\u001b[39m\n",
      "File \u001b[0;32m~/anaconda3/lib/python3.10/site-packages/IPython/core/ultratb.py:1021\u001b[0m, in \u001b[0;36mVerboseTB.get_records\u001b[0;34m(self, etb, number_of_lines_of_context, tb_offset)\u001b[0m\n\u001b[1;32m   1019\u001b[0m \u001b[39mwhile\u001b[39;00m cf \u001b[39mis\u001b[39;00m \u001b[39mnot\u001b[39;00m \u001b[39mNone\u001b[39;00m:\n\u001b[1;32m   1020\u001b[0m     \u001b[39mtry\u001b[39;00m:\n\u001b[0;32m-> 1021\u001b[0m         source_file \u001b[39m=\u001b[39m inspect\u001b[39m.\u001b[39mgetsourcefile(etb\u001b[39m.\u001b[39;49mtb_frame)\n\u001b[1;32m   1022\u001b[0m         lines, first \u001b[39m=\u001b[39m inspect\u001b[39m.\u001b[39mgetsourcelines(etb\u001b[39m.\u001b[39mtb_frame)\n\u001b[1;32m   1023\u001b[0m     \u001b[39mexcept\u001b[39;00m \u001b[39mOSError\u001b[39;00m:\n",
      "\u001b[0;31mAttributeError\u001b[0m: 'tuple' object has no attribute 'tb_frame'"
     ]
    }
   ],
   "source": [
    "unittest.main()"
   ]
  },
  {
   "cell_type": "markdown",
   "metadata": {},
   "source": [
    "Yikes! **<font color=red>SystemExit:</font> True** means an error occurred, as expected.  The reason is that `unittest.main( )` looks at *sys.argv*.  In Jupyter, by default, the first parameter of *sys.argv* is what started the Jupyter kernel which is not the case when executing it from the command line.  This default parameter is passed into `unittest.main( )` as an attribute when you don't explicitly pass it attributes and is therefore what causes the error about the kernel connection file not being a valid attribute. Passing an explicit list to `unittest.main( )` prevents it from looking at *sys.argv*. \n",
    "<br><br>Let's pass it the list ['first-arg-is-ignored'] for example.  In addition, we will pass it the parameter *exit = False* to prevent `unittest.main( )` from shutting down the kernel process.  Run the following cell with the *argv* and *exit* parameters passed into `unittest.main( )` to rerun your automatic test."
   ]
  },
  {
   "cell_type": "code",
   "execution_count": null,
   "metadata": {},
   "outputs": [
    {
     "name": "stderr",
     "output_type": "stream",
     "text": [
      ".\n",
      "----------------------------------------------------------------------\n",
      "Ran 1 test in 0.002s\n",
      "\n",
      "OK\n"
     ]
    },
    {
     "data": {
      "text/plain": [
       "<unittest.main.TestProgram at 0x7f32a9f73250>"
      ]
     },
     "execution_count": 24,
     "metadata": {},
     "output_type": "execute_result"
    }
   ],
   "source": [
    "unittest.main(argv=['first-arg-is-ignored'], exit=False)"
   ]
  },
  {
   "cell_type": "markdown",
   "metadata": {},
   "source": [
    "Did your automatic test pass? Was **OK** the result? If not, go back to your automatic test code and make sure you filled in the blanks correctly.  If your automatic test passed, great! You have successfully filled in the gaps to create an automatic test that verifies whether input strings have the correct list of string matches."
   ]
  },
  {
   "cell_type": "markdown",
   "metadata": {},
   "source": [
    "This is great work so far, but your automatic test includes only one test case.  You need to make it grow.  You can feed in more strings as test cases to test whether your code works in the general case.  But you should also see what happens when you give it some input that you might not expect it to run into under normal operations. \n",
    "<br><br>\n",
    "Edge cases are inputs to code that produce unexpected results, and are found at the extreme ends of the ranges of input we imagine programs will typically work with.  Can you use the cell below to write some edge cases? We've already filled in another test case for you! As it is, this test will run fine. Can you come up with at least one test case that you think could result in a wrong return value? No wrong answers! Feel free to play around."
   ]
  },
  {
   "cell_type": "code",
   "execution_count": null,
   "metadata": {},
   "outputs": [
    {
     "name": "stderr",
     "output_type": "stream",
     "text": [
      "..\n",
      "----------------------------------------------------------------------\n",
      "Ran 2 tests in 0.002s\n",
      "\n",
      "OK\n"
     ]
    },
    {
     "data": {
      "text/plain": [
       "<unittest.main.TestProgram at 0x7f32b9a4f310>"
      ]
     },
     "execution_count": 25,
     "metadata": {},
     "output_type": "execute_result"
    }
   ],
   "source": [
    "class TestCompiler2(unittest.TestCase):\n",
    "    def test_two(self):\n",
    "        testcase = \"A b c d e f g h i j k l m n o q r s t u v w x y z\"\n",
    "        expected = ['b', 'c']\n",
    "        self.assertEqual(LetterCompiler(testcase), expected)\n",
    "# EDGE CASES HERE\n",
    "\n",
    "unittest.main(argv=['first-arg-is-ignored'], exit=False)"
   ]
  },
  {
   "cell_type": "markdown",
   "metadata": {},
   "source": [
    "Did you find any edge cases?  If not, continue working on it.  Choosing test cases can be an exercise in creativity.  Coming up with different ways a code might break can be super fun! When you have found an edge case, think about special handling in your script in order for your code to continue to behave correctly.\n",
    "<br>\n",
    "If you are out of ideas: Try removing the spaces and figure out why they were in the example testcase. Does that give you an idea for other tests?\n",
    "<br>\n",
    "When you have found at least one edge case, you are all done with this notebook.  You should take a moment to reflect on what you've done so far.  It's super impressive and it's going to fit nicely in your IT toolkit."
   ]
  }
 ],
 "metadata": {
  "kernelspec": {
   "display_name": "Python 3",
   "language": "python",
   "name": "python3"
  },
  "language_info": {
   "codemirror_mode": {
    "name": "ipython",
    "version": 3
   },
   "file_extension": ".py",
   "mimetype": "text/x-python",
   "name": "python",
   "nbconvert_exporter": "python",
   "pygments_lexer": "ipython3",
   "version": "3.10.10"
  }
 },
 "nbformat": 4,
 "nbformat_minor": 2
}
